const x = '10';

try {
  x= 2
} catch (error) {
  console.log(`Ocorreu o seguinte errp: ${error}`);
}

console.log('A execução está em processo');